Workbook

Sheet Data Dictionary
A1: Field | B1: Type (from schema) | C1: Populated in sample (of 10) | D1: Max length in sample (chars) | E1: Example value(s) from sample | F1: Description (based on sample only) | G1: Status | H1: Data quality checks (sample-driven) | I1: Excel formula example (text) | J1: Description from public sources (only for fields not seen in sample) | K1: Source link | L1: Basis of description | M1: Confidence | N1: Used in sales intelligence platform? (Yes / Partial / No) | O1: Platform stage (Identify / Prioritise / Target) | P1: How it helps (if Yes or Partial) | Q1: Reason not used (if No)
A2: data | B2: VARCHAR | C2: 5 | D2: 923 | E2: HTTP/1.1 400 Bad Request Server: nginx Date: Mon, 14 Sep 2... | HTTP/1.1 403 Forbidden Content-Length:0 | HTTP/1.1 200 OK Date: Mon, 14 Sep 2026 12:01:50 GMT Server... | F2: Raw text response (banner) received from the service. In the sample it holds HTTP response headers (status line, Server, Date, Content-Type...) or an SSH banner string. Null in 5 of 10 rows. | G2: Observed in sample | H2: Null is common (5/10) so track % null by port/module; when null, hash is 0.0 (see hash); check HTTP banners start with 'HTTP/'; SSH row stores backslash-r backslash-n as literal characters while HTTP rows contain real CR/LF - standardize; length max 923 in sample, keep under Excel's 32,767 limit. | I2: =COUNTBLANK(A2:A11) | =IF(A2="","",LEFT(A2,5)="HTTP/") | J2: n/a - described from sample | N2: Partial | O2: Prioritise | P2: Raw banner is the evidence behind other fields; mine it for software name/version when product/version are null.
A3: opts | B3: MAP(VARCHAR, JSON) | C3: 10 | D3: 53 | E3: {} | {'raw': '"5353482d35382d496e677269616e5f5353480d0a"'} | F3: Map of extra key/values. Empty {} in 9 of 10 rows (empty, not null); one row has key 'raw' holding a hex string that decodes to the same SSH banner shown in data. | G3: Observed in sample | H3: Never null in sample; treat {} as 'no options'; if key 'raw' present it should be valid hex (even length, 0-9a-f). | I3: =A2="{}" | J3: n/a - described from sample | N3: No | Q3: Experimental/raw data (a hex string in the sample) with no business meaning; not finalized into a stable field.
A4: port | B4: BIGINT | C4: 10 | D4: 5 | E4: 15123 | 8008 | 53 | F4: Port number of the service on the IP. Sample values: 15123, 8008, 53, 12304, 7171, 48012, 80, 7171, 12304, 44818 (includes high, non-standard ports). | G4: Observed in sample | H4: Not null; integer 1-65535; do not assume standard ports - sample has many unusual ones; check port vs _shodan.module (e.g. port 53 -> dns-tcp, 80 -> http, 7171 -> tibia in sample). | I4: =AND(ISNUMBER(A2),A2=INT(A2),A2>=1,A2<=65535) | J4: n/a - described from sample | N4: Yes | O4: Prioritise | P4: Shows which services are exposed to the internet. Ports such as RDP, SMB, databases and Redis raise risk and urgency.
A5: hostnames | B5: VARCHAR[] | C5: 10 | D5: 42 | E5: [] | ['193.64.79.136.bc.googleusercontent.com'] | ['ip-137-66-8-132.customer.flyio.net'] | F5: Reverse-DNS hostnames for the IP, stored as a list. In the CSV it is the text form ['name'] ; empty list [] in 4 of 10 rows, 1 name in 6 rows (e.g. *.bc.googleusercontent.com, 77-163-107-27.fixed.kpn.net). | G5: Observed in sample | H5: Never null but can be '[]' (4/10) - treat '[]' as empty; list text begins '[' and ends ']'; hostnames usually embed the IP in sample - optional cross-check; domains should be suffix of hostname. | I5: =AND(LEFT(A2,1)="[",RIGHT(A2,1)="]") | =A2="[]" | J5: n/a - described from sample | N5: Yes | O5: Identify | P5: Reverse-DNS names link an IP to a company or hosting provider (e.g. kpn.net, flyio.net in the sample).
A6: timestamp | B6: VARCHAR | C6: 10 | D6: 26 | E6: 2026-09-14T09:59:27.083391 | 2026-09-14T09:59:56.544376 | 2026-09-14T09:59:58.072744 | F6: Date-time the record was collected, text like 2026-09-14T09:59:27.083391 (ISO style, microseconds, no timezone). Sample range 2026-09-14 09:59:27 to 10:00:11. | G6: Observed in sample | H6: Not null; parse with LEFT(A2,19); not in the future; format consistent (T separator, 6-digit fraction); timezone not stated in data so do not assume. Note http.headers.date for one row (12:01:50 GMT) is later than its timestamp (09:59:34) - device clock vs scan time, review. | I6: =IFERROR(DATEVALUE(LEFT(A2,10))+TIMEVALUE(MID(A2,12,8)),"BAD") | J6: n/a - described from sample | N6: Yes | O6: Prioritise | P6: Freshness of the signal; use for recency scoring and to drop stale findings.
A7: domains | B7: VARCHAR[] | C7: 10 | D7: 25 | E7: [] | ['googleusercontent.com'] | ['flyio.net'] | F7: Registered domain(s) derived from hostnames, stored as a list. [] in 4 of 10 rows; otherwise one domain (googleusercontent.com, flyio.net, kpn.net, incapdns.net). | G7: Observed in sample | H7: Empty exactly when hostnames is empty (true in all 10 sample rows); each domain should be contained in a hostname; lowercase; no scheme/path. | I7: =(A2="[]")=(B2="[]") (A=domains, B=hostnames) | J7: n/a - described from sample | N7: Yes | O7: Identify | P7: Main join key to company records (firmographics, CRM). Empty in 4 of 10 sample rows, so needs fallback keys.
A8: location | B8: STRUCT | C8: 10 | D8: 229 | E8: {'area_code': None, 'city': 'Tseung Kwan O', 'country_code':... | {'area_code': None, 'city': 'Tangjin', 'country_code': 'KR',... | {'area_code': None, 'city': 'Mountain View', 'country_code':... | F8: IP geolocation struct with city, country_code, country_name, latitude, longitude, region_code (populated); area_code, country_code3, dma_code, postal_code were null in all 10 rows. See sub-field rows. | G8: Observed in sample | H8: Struct present 10/10; check sub-fields individually. | I8: =COUNTBLANK(A2:A11) | J8: n/a - described from sample | N8: Yes | O8: Target | P8: Country/region/city for territory routing and regional targeting. See sub-fields for what is reliable.
A9: org | B9: VARCHAR | C9: 10 | D9: 25 | E9: Meteverse Limited. | Korea Telecom | Google LLC | F9: Organization name for the IP (e.g. Google LLC, Korea Telecom, KPN B.V., Fly.io, Inc.). Populated 10/10. | G9: Observed in sample | H9: Not null in sample; trim; naming inconsistent punctuation (e.g. 'Meteverse Limited.' with trailing period); org may differ from isp (Aliyun Computing Co., LTD vs Hangzhou Alibaba Advertising Co.,Ltd.) - do not force equality. | I9: =EXACT(A2,TRIM(A2)) | J9: n/a - described from sample | N9: Yes | O9: Identify | P9: Organization that manages the IP; primary company-name signal. Often a cloud/ISP rather than the end customer (Google LLC in sample), so filter those out.
A10: isp | B10: VARCHAR | C10: 9 | D10: 37 | E10: Meteverse Limited. | Korea Telecom | Fly.io, Inc. | F10: Internet service provider name. Populated 9/10; null for the same row where asn is null. | G10: Observed in sample | H10: Null rate 10% in sample; isp and asn null together (row 3) - check pair null-consistency; trim. | I10: =(A2="")=(B2="") (A=isp, B=asn) | J10: n/a - described from sample | N10: Partial | O10: Identify | P10: Helps tell self-hosted infrastructure from hosted/cloud; the ISP itself is not a lead.
A11: os | B11: VARCHAR | C11: 0 | D11: 0 | E11: (all null) | F11: Operating system. NULL in all 10 sample rows, so no real values observed. | G11: Not observed (all null) | H11: 100% null in sample - confirm with a larger extract before applying value checks. | I11: =COUNTBLANK(A2:A11)=ROWS(A2:A11) | J11: Operating system of the host (Datapedia describes it only as 'Operating system'). | K11: https://datapedia.shodan.io/ | L11: Shodan Datapedia - text on page | M11: High | N11: Partial | O11: Prioritise | P11: Outdated operating systems are a strong need signal, but the column was null in all 10 sample rows. Validate coverage first.
A12: product | B12: VARCHAR | C12: 4 | D12: 14 | E12: nginx | Chromecast | Boa Web Server | F12: Detected software/product name. Populated 4/10: nginx, Chromecast, Boa Web Server, Ingrian SSH. | G12: Observed in sample | H12: 60% null; when product is present it should relate to banner (nginx <-> Server: nginx; Ingrian SSH <-> SSH banner); version is null in all rows even when product present. | I12: =IF(A2="","",ISNUMBER(SEARCH(A2,B2))) (B=data) | J12: n/a - described from sample | N12: Yes | O12: Prioritise | P12: Names the software on the port; basis for outdated/exposed software findings. Null in 6 of 10 sample rows.
A13: http | B13: STRUCT | C13: 3 | D13: 34410 | E13: {'status': 400, 'robots_hash': None, 'redirects': [], 'title... | {'status': 403, 'robots_hash': None, 'redirects': [], 'title... | {'status': 200, 'robots_hash': None, 'redirects': [], 'title... | F13: Struct for web services: status, title, server, headers, html, hashes, components, redirects, host, location, etc. Present in 3/10 rows (ports 15123, 8008 and 80). See sub-field rows. | G13: Observed in sample | H13: Null for non-HTTP rows (7/10); entire cell text can exceed Excel's 32,767-char limit (one row is ~34,410 chars) - process in DuckDB, or flatten sub-fields. | I13: =LEN(A2)>32767 | J13: n/a - described from sample | N13: Yes | O13: Identify | P13: Web data: status, title, server, technologies, WAF. Gives the tech stack and website identity of the business.
A14: ip | B14: BIGINT | C14: 10 | D14: 10 | E14: 2322677098 | 3667294341 | 2286895297 | F14: IPv4 address as integer. Matched ip_str in all 10 sample rows (e.g. 2322677098 = 138.113.61.106). | G14: Observed in sample | H14: Not null; 0-4294967295; equals integer form of ip_str (verified 10/10). | I14: =A2=INDEX_OCTET_FORMULA (see Row-Level Checks) | J14: n/a - described from sample | N14: No | Q14: Numeric duplicate of ip_str (matched in 10/10 sample rows); useful only for faster storage/range queries.
A15: cpe23 | B15: VARCHAR[] | C15: 2 | D15: 62 | E15: ['cpe:2.3:a:f5:nginx'] | ['cpe:2.3:a:jquery:jquery' 'cpe:2.3:a:jquery:jquery_ui:1.7.2... | F15: Software identifiers in CPE 2.3 text form, as a list. Populated 2/10, e.g. cpe:2.3:a:f5:nginx and cpe:2.3:a:jquery:jquery_ui:1.7.2. Values in sample are short (not full 13-field CPE strings). | G15: Observed in sample | H15: Starts with 'cpe:2.3:'; do not require 13 parts (sample values have 5-6); null when cpe is null (8/10 both); element count equals cpe. | I15: =IF(A2="","",ISNUMBER(SEARCH("cpe:2.3:",A2))) | J15: n/a - described from sample | N15: Yes | O15: Prioritise | P15: Standard software identifier that can be matched to known vulnerabilities. Only 2 of 10 sample rows have it.
A16: cpe | B16: VARCHAR[] | C16: 2 | D16: 56 | E16: ['cpe:/a:f5:nginx'] | ['cpe:/a:jquery:jquery' 'cpe:/a:jquery:jquery_ui:1.7.2'] | F16: Same identifiers in CPE 2.2 style, e.g. cpe:/a:f5:nginx. Populated 2/10 (same rows as cpe23). | G16: Observed in sample | H16: Starts with 'cpe:/'; null exactly when cpe23 null. | I16: =IF(A2="","",ISNUMBER(SEARCH("cpe:/",A2))) | J16: n/a - described from sample | N16: No | Q16: Older deprecated format of the same information as cpe23 (Datapedia calls it the old, deprecated format).
A17: _shodan | B17: STRUCT | C17: 10 | D17: 180 | E17: {'options': {}, 'module': 'auto', 'id': UUID('90cc99c7-b355-... | {'options': {}, 'module': 'http-simple-new', 'id': UUID('5c6... | {'options': {}, 'module': 'dns-tcp', 'id': UUID('59f89bf4-f5... | F17: Collection metadata struct: options (empty {} in all rows), module (auto, http, http-simple-new, dns-tcp, tibia, ethernetip), id (UUID), crawler (40-char hex), region (na, eu or empty string), ptr (TRUE or null). Populated 10/10. | G17: Observed in sample | H17: See sub-field rows. id unique per row (10/10 unique in sample). | I17: =COUNTBLANK(A2:A11) | J17: n/a - described from sample | N17: No | Q17: Metadata about how the banner was collected (Datapedia: it stores no data about the service itself). Keep only for deduplication and lineage.
A18: cpe23_hash | B18: DOUBLE | C18: 2 | D18: 13 | E18: -1725627573.0 | 1072693929.0 | F18: Numeric value tied to cpe23. Populated 2/10 (same rows as cpe23); values can be negative (-1725627573, 1072693929). | G18: Observed in sample | H18: Null exactly when cpe23 null (true in sample); numeric; negative values valid. | I18: =(A2="")=(B2="") (B=cpe23) | J18: n/a - described from sample | N18: No | Q18: Numeric fingerprint for grouping identical software; no direct business meaning. Engineering use only.
A19: hash | B19: DOUBLE | C19: 10 | D19: 13 | E19: 867632950.0 | -1437137619.0 | 0.0 | F19: Numeric value per record, never null. Equals 0.0 in the 5 rows where data is null; non-zero otherwise (e.g. 867632950, -1437137619). | G19: Observed in sample | H19: Never null; hash = 0 exactly when data is null (5/5 in sample) - use as consistency check; negative values valid. | I19: =(A2=0)=(B2="") (B=data) | J19: n/a - described from sample | N19: No | Q19: Numeric hash of the banner used to group identical banners. Engineering use only; equals 0 when data is null.
A20: transport | B20: VARCHAR | C20: 10 | D20: 3 | E20: tcp | F20: Transport protocol. 'tcp' in all 10 sample rows. | G20: Observed in sample | H20: Allowed values tcp/udp (only tcp observed); lowercase; not null. | I20: =OR(A2="tcp",A2="udp") | J20: n/a - described from sample | N20: Partial | O20: Prioritise | P20: UDP-exposed services (e.g. NTP, SNMP) can be abused for amplification attacks; context only, always tcp in sample.
A21: ip_str | B21: VARCHAR | C21: 10 | D21: 15 | E21: 138.113.61.106 | 218.150.120.133 | 136.79.64.193 | F21: IPv4 address in dotted text (e.g. 138.113.61.106). | G21: Observed in sample | H21: Not null; 4 octets 0-255; matches ip; no spaces. | I21: =AND(LEN(A2)-LEN(SUBSTITUTE(A2,".",""))=3,ISERROR(SEARCH(" ",A2))) | J21: n/a - described from sample | N21: Yes | O21: Identify | P21: Readable IP used to join to company IP ranges and ASN data.
A22: asn | B22: VARCHAR | C22: 9 | D22: 8 | E22: AS54994 | AS4766 | AS40509 | F22: Autonomous system number as text with 'AS' prefix (e.g. AS54994, AS3356, AS396982). 9/10 populated. | G22: Observed in sample | H22: Pattern 'AS' + digits; same ASN repeated for different IPs (AS396982 twice) is normal; null with isp null. | I22: =IF(A2="","",AND(LEFT(A2,2)="AS",ISNUMBER(--MID(A2,3,10)))) | J22: n/a - described from sample | N22: Yes | O22: Identify | P22: Groups IPs into a company's network so exposed assets can be attributed to one organization. Null in 1 of 10 sample rows.
A23: tags | B23: VARCHAR[] | C23: 4 | D23: 9 | E23: ['iot'] | ['cloud'] | ['cdn'] | F23: Labels list. Populated 4/10: ['iot'], ['cloud'] (x2), ['cdn']. | G23: Observed in sample | H23: 60% null; values observed: iot, cloud, cdn - maintain allowed list as more values appear; cloud tag appears on rows where cloud struct is populated (2/2). | I23: =IF(A2="","",LEFT(A2,1)="[") | J23: n/a - described from sample | N23: Yes | O23: Prioritise | P23: Ready-made risk labels. Datapedia lists values like eol-os, eol-product, self-signed, compromised, malware, vpn, ics. Use 'honeypot' to exclude false leads.
A24: dns | B24: STRUCT | C24: 1 | D24: 86 | E24: {'resolver_hostname': None, 'recursive': False, 'resolver_id... | F24: DNS-related struct (resolver_hostname, recursive, resolver_id, software). 1/10 populated, on the port 53 row; recursive=False, others null. | G24: Observed in sample | H24: Present only on port 53 row in sample; recursive TRUE/FALSE. | I24: =IF(A2="","",OR(A2=TRUE,A2=FALSE)) | J24: n/a - described from sample | N24: Partial | O24: Prioritise | P24: dns.recursive shows an open resolver, a hygiene issue; narrow signal.
A25: cloud | B25: STRUCT | C25: 2 | D25: 59 | E25: {'region': 'global', 'service': None, 'provider': 'Google'} | F25: Cloud struct (provider, region, service). 2/10 populated: provider Google, region global, service null; both rows have org Google LLC and tag cloud. | G25: Observed in sample | H25: Null for non-cloud (8/10); provider consistent with org; service null in sample. | I25: =COUNTBLANK(A2:A11) | J25: n/a - described from sample | N25: Partial | O25: Target | P25: Separates cloud-hosted from on-premise estates, useful for choosing cloud vs network security offers.
A26: screenshot | B26: STRUCT | C26: 1 | D26: 58252 | E26: {'mime': 'image/jpeg', 'data': '/9j/4AAQSkZJRgABAQAAAQABAAD/... | F26: Screenshot struct: mime (image/jpeg), data (base64 text with line breaks), hash, labels (['webcam','login']). 1/10 populated, on the port 80 row. | G26: Observed in sample | H26: Null 9/10; mime starts 'image/'; data is large - exceeds Excel 32,767-char cell limit, keep in DuckDB; labels list non-empty. | I26: =LEN(A2)>32767 | J26: n/a - described from sample | N26: Partial | O26: Prioritise | P26: Use only the labels (e.g. webcam, login) to spot exposed login panels or cameras. Do not store the base64 image (58,252 chars in sample).
A27: version | B27: VARCHAR | C27: 0 | D27: 0 | E27: (all null) | F27: NULL in all 10 sample rows - meaning not verifiable from this sample; only the column name and declared type are known. | G27: Not observed (all null) | H27: Cannot define value rules from this sample. Only check: percent null across a larger extract; type matches schema (VARCHAR). | I27: =COUNTBLANK(A2:A11) | J27: Version string of the software on the port. Datapedia lists it as a string with no description; it sits next to 'product' (name of the software that powers the service). | K27: https://datapedia.shodan.io/ | L27: Datapedia lists the field with no description; meaning inferred from field name | M27: Medium | N27: Yes | O27: Prioritise | P27: With product, identifies outdated versions. Null in all 10 sample rows, so check coverage.
A28: devicetype | B28: VARCHAR | C28: 1 | D28: 13 | E28: security-misc | F28: Device category text. 1/10 populated: 'security-misc' (on the Ingrian SSH row). | G28: Observed in sample | H28: 90% null; build allowed list as data grows. | I28: =COUNTBLANK(A2:A11) | J28: n/a - described from sample | N28: Partial | O28: Target | P28: Helps segment by environment (e.g. ICS, medical, IoT). 1 of 10 rows populated in sample.
A29: info | B29: VARCHAR | C29: 1 | D29: 11 | E29: protocol 58 | F29: Extra info text. 1/10 populated: 'protocol 58' (Ingrian SSH row). | G29: Observed in sample | H29: 90% null; trimmed. | I29: =COUNTBLANK(A2:A11) | J29: n/a - described from sample | N29: No | Q29: Free text with no standard format; 1 of 10 rows populated ('protocol 58').
A30: ipv6 | B30: VARCHAR | C30: 0 | D30: 0 | E30: (all null) | F30: NULL in all 10 sample rows - meaning not verifiable from this sample; only the column name and declared type are known. | G30: Not observed (all null) | H30: Cannot define value rules from this sample. Only check: percent null across a larger extract; type matches schema (VARCHAR). | I30: =COUNTBLANK(A2:A11) | J30: IPv6 address of the host. Datapedia lists it as a string with no description. Name suggests it is used when the service was found over IPv6 instead of ip/ip_str. | K30: https://datapedia.shodan.io/ | L30: Datapedia lists the field with no description; meaning inferred from field name | M30: Medium | N30: No | Q30: Null in all 10 sample rows; IPv4 fields already identify the host.
A31: ssl | B31: STRUCT | C31: 0 | D31: 0 | E31: (all null) | F31: NULL in all 10 sample rows - meaning not verifiable from this sample; only the column name and declared type are known. | G31: Not observed (all null) | H31: Cannot define value rules from this sample. Only check: percent null across a larger extract; type matches schema (STRUCT). | I31: =COUNTBLANK(A2:A11) | J31: Parsed TLS/SSL data for the service: parsed certificate (ssl.cert), certificate chain, list of SSL/TLS versions the device permits and denies (denied ones prefixed with '-'), and the preferred cipher. Also holds fingerprints jarm (active TLS server fingerprint) and ja3s (server-side TLS fingerprint). | K31: https://blog.shodan.io/ssl-update/ | L31: Shodan blog + Datapedia | M31: High | N31: Yes | O31: Identify | P31: Certificate subject/issuer can name the company; expired certs, old SSL/TLS versions and self-signed certs show weak hygiene. Null in sample.
A32: vulns | B32: MAP(VARCHAR, STRUCT) | C32: 0 | D32: 0 | E32: (all null) | F32: NULL in all 10 sample rows - meaning not verifiable from this sample; only the column name and declared type are known. | G32: Not observed (all null) | H32: Cannot define value rules from this sample. Only check: percent null across a larger extract; type matches schema (MAP(VARCHAR, STRUCT)). | I32: =COUNTBLANK(A2:A11) | J32: Map keyed by vulnerability ID. Each entry has cvss, cvss_version, epss, ranking_epss, kev, verified, references and summary (Datapedia lists these fields; 'references', 'summary' and 'verified' are required). Standard meanings: CVSS = severity score, EPSS = predicted exploitation probability, KEV = listed in a known-exploited catalog. | K32: https://datapedia.shodan.io/ | L32: Shodan Datapedia lists this property (no prose description); meaning = standard protocol/product meaning | M32: Medium | N32: Yes | O32: Prioritise | P32: Strongest buying signal: known CVEs with CVSS, EPSS and KEV flags. Null in sample, so confirm coverage.
A33: title | B33: VARCHAR | C33: 0 | D33: 0 | E33: (all null) | F33: NULL in all 10 sample rows - meaning not verifiable from this sample; only the column name and declared type are known. | G33: Not observed (all null) | H33: Cannot define value rules from this sample. Only check: percent null across a larger extract; type matches schema (VARCHAR). | I33: =COUNTBLANK(A2:A11) | J33: Deprecated. Datapedia says to use http.title instead. Matches your sample, where top-level title was null while http.title was populated. | K33: https://datapedia.shodan.io/ | L33: Shodan Datapedia - text on page | M33: High | N33: No | Q33: Deprecated per Datapedia; use http.title. Null in all 10 sample rows.
A34: html | B34: VARCHAR | C34: 0 | D34: 0 | E34: (all null) | F34: NULL in all 10 sample rows - meaning not verifiable from this sample; only the column name and declared type are known. | G34: Not observed (all null) | H34: Cannot define value rules from this sample. Only check: percent null across a larger extract; type matches schema (VARCHAR). | I34: =COUNTBLANK(A2:A11) | J34: Deprecated. Datapedia says to use http.html instead. Matches your sample, where top-level html was null while http.html was populated. | K34: https://datapedia.shodan.io/ | L34: Shodan Datapedia - text on page | M34: High | N34: No | Q34: Deprecated per Datapedia; use http.html. Null in all 10 sample rows.
A35: ssh | B35: STRUCT | C35: 0 | D35: 0 | E35: (all null) | F35: NULL in all 10 sample rows - meaning not verifiable from this sample; only the column name and declared type are known. | G35: Not observed (all null) | H35: Cannot define value rules from this sample. Only check: percent null across a larger extract; type matches schema (STRUCT). | I35: =COUNTBLANK(A2:A11) | J35: SSH service details gathered during the handshake: server host key and fingerprint, key-exchange, encryption, MAC and compression algorithm lists, and a HASSH fingerprint. Datapedia also defines the tag 'ssh-bad-key'. | K35: https://datapedia.shodan.io/property/ssh.html | L35: Shodan Datapedia lists this property (no prose description); meaning = standard protocol/product meaning | M35: Medium | N35: Partial | O35: Prioritise | P35: Weak key-exchange/cipher lists or known bad keys point to poor hardening.
A36: mdns | B36: STRUCT | C36: 0 | D36: 0 | E36: (all null) | F36: NULL in all 10 sample rows - meaning not verifiable from this sample; only the column name and declared type are known. | G36: Not observed (all null) | H36: Cannot define value rules from this sample. Only check: percent null across a larger extract; type matches schema (STRUCT). | I36: =COUNTBLANK(A2:A11) | J36: Multicast DNS (mDNS) service-discovery response: services a device advertises on a network (e.g. workstation, spotify-connect, mumble) with name, port and addresses. | K36: https://datapedia.shodan.io/property/mdns.html | L36: Shodan Datapedia lists this property (no prose description); meaning = standard protocol/product meaning | M36: Medium | N36: No | Q36: Local-network discovery protocol, mostly consumer/home devices; weak link to a business buyer.
A37: pptp | B37: STRUCT | C37: 0 | D37: 0 | E37: (all null) | F37: NULL in all 10 sample rows - meaning not verifiable from this sample; only the column name and declared type are known. | G37: Not observed (all null) | H37: Cannot define value rules from this sample. Only check: percent null across a larger extract; type matches schema (STRUCT). | I37: =COUNTBLANK(A2:A11) | J37: Point-to-Point Tunneling Protocol (VPN) server info: firmware, hostname and vendor reported by the server. | K37: https://datapedia.shodan.io/property/pptp.html | L37: Shodan Datapedia lists this property (no prose description); meaning = standard protocol/product meaning | M37: Medium | N37: Partial | O37: Prioritise | P37: PPTP is a legacy VPN protocol; its presence suggests outdated remote access. Narrow signal.
A38: plex | B38: STRUCT | C38: 0 | D38: 0 | E38: (all null) | F38: NULL in all 10 sample rows - meaning not verifiable from this sample; only the column name and declared type are known. | G38: Not observed (all null) | H38: Cannot define value rules from this sample. Only check: percent null across a larger extract; type matches schema (STRUCT). | I38: =COUNTBLANK(A2:A11) | J38: Plex Media Server identification; holds the server's machine_identifier. | K38: https://datapedia.shodan.io/property/plex.html | L38: Shodan Datapedia lists this property (no prose description); meaning = standard protocol/product meaning | M38: Medium | N38: No | Q38: Consumer media server software; not a business cybersecurity buying signal.
A39: snmp | B39: STRUCT | C39: 0 | D39: 0 | E39: (all null) | F39: NULL in all 10 sample rows - meaning not verifiable from this sample; only the column name and declared type are known. | G39: Not observed (all null) | H39: Cannot define value rules from this sample. Only check: percent null across a larger extract; type matches schema (STRUCT). | I39: =COUNTBLANK(A2:A11) | J39: Simple Network Management Protocol response: supported SNMP versions, engine ID details, engine boots/time and enterprise number/name of the device vendor. | K39: https://datapedia.shodan.io/property/snmp.html | L39: Shodan Datapedia lists this property (no prose description); meaning = standard protocol/product meaning | M39: Medium | N39: Partial | O39: Prioritise | P39: Internet-exposed device management; useful with SNMP version and vendor.
A40: mac | B40: MAP(VARCHAR, JSON) | C40: 0 | D40: 0 | E40: (all null) | F40: NULL in all 10 sample rows - meaning not verifiable from this sample; only the column name and declared type are known. | G40: Not observed (all null) | H40: Cannot define value rules from this sample. Only check: percent null across a larger extract; type matches schema (MAP(VARCHAR, JSON)). | I40: =COUNTBLANK(A2:A11) | J40: Map keyed by MAC address. Each value is MacAddressInfo with 'assignment', 'date' and 'org' (organization the MAC prefix is registered to); 'assignment' and 'org' are required. | K40: https://datapedia.shodan.io/ | L40: Shodan Datapedia - text on page | M40: High | N40: No | Q40: MAC vendor lookup of a local network address; little value for choosing company targets.
...

Sheet Sub-fields Observed
A1: Sub-field | B1: Type | C1: Description (based on sample only) | D1: Data quality checks | E1: Excel formula example (text) | F1: Used in sales intelligence platform? (Yes / Partial / No) | G1: Platform stage (Identify / Prioritise / Target) | H1: How it helps (if Yes or Partial) | I1: Reason not used (if No)
A2: location.city | B2: VARCHAR | C2: City, e.g. Tseung Kwan O, Mountain View, Dordrecht. 10/10 populated. | D2: Not null in sample; same city can map to same coordinates (Mountain View x2 share lat/long). | E2: =LEN(A2)>0 | F2: Yes | G2: Target | H2: City for territory routing; IP geolocation is approximate.
A3: location.country_code | B3: VARCHAR | C3: 2-letter country code: HK, KR, US, GB, NL, SG, CN. 10/10. | D3: Exactly 2 uppercase letters; matches country_name 1:1 (US->United States in 4 rows). | E3: =AND(LEN(A2)=2,EXACT(A2,UPPER(A2))) | F3: Yes | G3: Target | H3: Country filter for territory, regulation and language targeting.
A4: location.country_name | B4: VARCHAR | C4: Country name. Note 'Korea, Republic of' contains a comma. | D4: Comma inside value - quote when exporting to CSV; 1 name per code. | E4: =ISNUMBER(SEARCH(",",A2)) | F4: No | I4: Duplicates country_code; value 'Korea, Republic of' contains a comma.
A5: location.latitude | B5: DOUBLE | C5: Latitude, e.g. 22.32789. 10/10. | D5: Numeric between -90 and 90. | E5: =AND(A2>=-90,A2<=90) | F5: No | I5: IP geolocation points to hosting/ISP location, not the company office; in the sample two Google LLC rows share identical coordinates.
A6: location.longitude | B6: DOUBLE | C6: Longitude, e.g. 114.24992. 10/10. | D6: Numeric between -180 and 180. | E6: =AND(A2>=-180,A2<=180) | F6: No | I6: Same limitation as latitude.
A7: location.region_code | B7: VARCHAR | C7: Region/state code: '', 44, CA, ENG, MO, ZH, 01, MA, ZJ. Empty string '' appears in 1 row. | D7: Mixes empty string and null styles - normalize ''->NULL; formats vary (numeric vs letters). | E7: =A2="" | F7: Partial | G7: Target | H7: Region/state for finer territories, but formats vary and '' appears in the sample.
A8: location.area_code / country_code3 / dma_code / postal_code | B8: JSON/VARCHAR | C8: NULL in all 10 rows. | D8: 100% null in sample - confirm with larger data. | E8: =COUNTBLANK(A2:A11) | F8: No | I8: Null in all 10 sample rows.
A9: _shodan.module | B9: VARCHAR | C9: Name of scan module: auto (4), tibia (2), http, http-simple-new, dns-tcp, ethernetip. | D9: Not null; build allowed list; compare with port (53->dns-tcp, 44818->ethernetip). | E9: =LEN(A2)>0 | F9: No | I9: Collection detail already reflected by port/product; engineering use only.
A10: _shodan.id | B10: UUID | C10: Unique identifier per record (36-char UUID). 10 unique in 10 rows. | D10: Unique; 36 chars with 4 hyphens. | E10: =AND(LEN(A2)=36,LEN(A2)-LEN(SUBSTITUTE(A2,"-",""))=4) | F10: No | I10: Unique banner ID; use only for deduplication.
A11: _shodan.crawler | B11: VARCHAR | C11: 40-character hex string (crawler identifier). | D11: 40 hex characters. | E11: =LEN(A2)=40 | F11: No | I11: Scanner identifier; no business meaning.
A12: _shodan.region | B12: VARCHAR | C12: Values: na (6), eu (3), empty string (1). | D12: Normalize '' to NULL; allowed list na/eu seen so far. | E12: =OR(A2="na",A2="eu") | F12: No | I12: Scanner region (na/eu), not the target's location.
A13: _shodan.ptr | B13: BOOLEAN | C13: TRUE in 8 rows, null in 2 rows. | D13: TRUE/null only seen; FALSE not observed. | E13: =OR(A2=TRUE,A2="") | F13: No | I13: Collection flag; no business meaning.
A14: _shodan.options | B14: MAP | C14: Empty {} in all 10 rows. | D14: Expect {}. | E14: =A2="{}" | F14: No | I14: Empty in all 10 sample rows.
A15: http.status | B15: BIGINT | C15: HTTP status: 400, 403, 200 (3 rows). | D15: 100-599 integer; matches first line of data (HTTP/1.1 400 Bad Request etc. - consistent 3/3). | E15: =AND(A2>=100,A2<=599) | F15: Partial | G15: Prioritise | H15: 200 vs 403/400 shows whether a service answers openly or is blocked/misconfigured.
A16: http.host | B16: VARCHAR | C16: Equals ip_str in all 3 http rows. | D16: Equals ip_str. | E16: =A2=B2 (B=ip_str) | F16: No | I16: Equals ip_str in all 3 sample http rows.
A17: http.title | B17: VARCHAR | C17: Page title: '400 Bad Request' in 1 row; null in the other 2. NOTE top-level title column is null in all rows even when http.title exists, so top-level title is NOT a copy. | D17: Do not rely on top-level title; use http.title. | E17: =COUNTBLANK(A2:A11) | F17: Partial | G17: Identify | H17: Page title can name the site or reveal admin/login pages.
A18: http.server | B18: VARCHAR | C18: Server header value: nginx, Boa/0.94.14rc21; null in 1 row. | D18: Matches product for nginx and Boa rows; null when header absent. | E18: =IF(A2="","",ISNUMBER(SEARCH(A2,B2))) | F18: Yes | G18: Prioritise | H18: Web server name/version for outdated-software detection.
A19: http.headers | B19: MAP(VARCHAR,VARCHAR) | C19: Lower-case header names: content-length, server, date, content-type, connection, etc. | D19: Keys lowercase; values text; one row has only content-length: 0. | E19: =EXACT(A2,LOWER(A2)) | F19: Partial | G19: Prioritise | H19: Missing security headers show weak hardening; needs parsing.
A20: http.html | B20: VARCHAR | C20: Page HTML: full page in 2 rows, empty string '' in 1 row. Top-level html column is null in all rows (not a copy). | D20: '' vs null - when html is '' then dom_hash, html_hash and components_hash are 0.0 (row 2). | E20: =A2="" | F20: Partial | G20: Identify | H20: Mine for company name or product clues; very large, so extract text rather than store whole page.
A21: http.*_hash (title, dom, components, headers, html, server) | B21: DOUBLE | C21: Numeric values, can be negative; 0.0 when html is empty; null when source field null (title_hash null when title null in non-empty case). | D21: Numeric; consistent null/0 behavior. | E21: =ISNUMBER(A2) | F21: No | I21: Fingerprint hashes for clustering similar pages; engineering use only.
A22: http.location | B22: VARCHAR | C22: '/' in all 3 http rows. | D22: Not null in http rows. | E22: =A2="/" | F22: No | I22: '/' in all 3 sample rows.
A23: http.components | B23: MAP | C23: Detected web tech: Nginx (Web servers, Reverse proxies); jQuery and jQuery UI 1.7.2 (JavaScript libraries); {} empty in 1 row. | D23: versions can be null; {} for none. | E23: =A2="{}" | F23: Yes | G23: Prioritise | H23: Detected web technologies and versions (e.g. jQuery UI 1.7.2 in sample) show tech stack and outdated libraries.
A24: http.redirects / robots / securitytxt / sitemap / waf / favicon / identifiers | B24: various | C24: Empty list or null in all 3 http rows. | D24: Not verifiable from sample. | E24: =COUNTBLANK(A2:A11) | F24: Partial | G24: Target | H24: waf and securitytxt hint at security maturity; analytics/tag IDs can link sites to one company. Other parts are empty in the sample.
A25: screenshot.labels | B25: VARCHAR[] | C25: ['webcam','login'] on the single screenshot row. | D25: Values: webcam, login so far. | E25: =LEFT(A2,1)="[" | F25: Partial | G25: Prioritise | H25: Labels such as webcam or login flag exposed panels.

Sheet Row-Level Checks
A1: Check | B1: Fields | C1: Result on 10-row sample | D1: Excel formula example (text)
A2: ip equals integer form of ip_str | B2: ip, ip_str | C2: Passed 10/10 | D2: =VALUE(TRIM(MID(SUBSTITUTE(B2,".",REPT(" ",15)),1,15)))*16777216+VALUE(TRIM(MID(SUBSTITUTE(B2,".",REPT(" ",15)),16,15)))*65536+VALUE(TRIM(MID(SUBSTITUTE(B2,".",REPT(" ",15)),31,15)))*256+VALUE(TRIM(MID(SUBSTITUTE(B2,".",REPT(" ",15)),46,15)))=A2
A3: hash = 0 exactly when data is null | B3: hash, data | C3: Passed 10/10 (5 nulls, 5 zeros) | D3: =(A2=0)=(B2="")
A4: cpe23 null iff cpe null; cpe23_hash null iff cpe23 null | B4: cpe23, cpe, cpe23_hash | C4: Passed 10/10 (same 2 rows) | D4: =(A2="")=(B2="")
A5: domains empty iff hostnames empty | B5: domains, hostnames | C5: Passed 10/10 | D5: =(A2="[]")=(B2="[]")
A6: http.status matches first line of data | B6: http.status, data | C6: Passed 3/3 where both present (400, 403, 200) | D6: =ISNUMBER(SEARCH(A2,B2))
A7: isp null iff asn null | B7: isp, asn | C7: Passed 10/10 (1 row) | D7: =(A2="")=(B2="")
A8: _shodan.id unique | B8: _shodan.id | C8: Passed 10/10 | D8: =COUNTIF($A$2:$A$11,A2)=1
A9: Duplicate ip_str + port | B9: ip_str, port | C9: No duplicates (7171 and 12304 repeat but on different IPs) | D9: =COUNTIFS($A$2:$A$11,A2,$B$2:$B$11,B2)>1
A10: Cell exceeds Excel 32,767 chars | B10: http, screenshot | C10: FAILED: http row 7 is ~34,410 chars; screenshot data is also large | D10: =LEN(A2)>32767
A11: Empty string vs NULL consistency | B11: location.region_code, _shodan.region, http.html | C11: Mixed: '' appears in location.region_code (1), _shodan.region (1), http.html (1) | D11: =A2=""
A12: Top-level title/html vs http.title/html | B12: title, html, http.title, http.html | C12: Top-level title/html null in 10/10 while http.title/html populated - not duplicates | D12: =AND(A2="",B2<>"")

Sheet Sample Profile
A1: Field | B1: Non-null (of 10) | C1: Null (of 10) | D1: Null % | E1: Distinct non-null
A2: data | B2: 5 | C2: =10-B2 -> 5 | D2: =C2/10 -> 0.5 | E2: 5
A3: opts | B3: 10 | C3: =10-B3 -> 0 | D3: =C3/10 -> 0 | E3: 2
A4: port | B4: 10 | C4: =10-B4 -> 0 | D4: =C4/10 -> 0 | E4: 8
A5: hostnames | B5: 10 | C5: =10-B5 -> 0 | D5: =C5/10 -> 0 | E5: 7
A6: timestamp | B6: 10 | C6: =10-B6 -> 0 | D6: =C6/10 -> 0 | E6: 10
A7: domains | B7: 10 | C7: =10-B7 -> 0 | D7: =C7/10 -> 0 | E7: 5
A8: location | B8: 10 | C8: =10-B8 -> 0 | D8: =C8/10 -> 0 | E8: 9
A9: org | B9: 10 | C9: =10-B9 -> 0 | D9: =C9/10 -> 0 | E9: 8
A10: isp | B10: 9 | C10: =10-B10 -> 1 | D10: =C10/10 -> 0.1 | E10: 8
A11: os | B11: 0 | C11: =10-B11 -> 10 | D11: =C11/10 -> 1 | E11: 0
A12: product | B12: 4 | C12: =10-B12 -> 6 | D12: =C12/10 -> 0.6 | E12: 4
A13: http | B13: 3 | C13: =10-B13 -> 7 | D13: =C13/10 -> 0.7 | E13: 3
... A63: mcp | B63: 0 | C63: =10-B63 -> 10 | D63: =C63/10 -> 1 | E63: 0
A65: Source: bronze_sample_10_rows.csv (10 rows x 62 columns). Counts of non-null/distinct are values read from that file; null counts and % are formulas.

Sheet Notes
A1: Notes on this version
A2: 1. Every description is based only on the 10-row sample. Where a column was null in all 10 rows, the dictionary says so and does not guess a meaning.
A3: 2. Types come from the DuckDB schema you pasted earlier. Struct/map/list columns appear in the CSV as text like {'k': v} or ['x'].
A4: 3. Example formulas are text and assume the field is in column A, rows 2-11. Change the range for a bigger dataset.
A5: 4. With only 10 rows, 'allowed lists' (tags, module, devicetype) are what was seen so far, not complete lists. Re-profile on a larger extract.
A6: 5. Corrections vs the earlier version: top-level title/html are NOT copies of http.title/http.html; cpe23 values are short (not full 13-part strings); hash can be negative and is 0 when data is null.
A7: 7. Sales-intelligence columns: Shodan data describes IP addresses and services, not companies. To use it, first attribute IPs to a company (domains, hostnames, org, asn, ssl certificate subject), then score exposure signals (vulns, tags, risky ports, outdated software), then route by location.

Sheet Sources
A1: Source | B1: URL | C1: Used for
A2: Shodan Datapedia - overview / general properties | B2: https://datapedia.shodan.io/ | C2: Top-level fields: os, version, ipv6, title (deprecated), html (deprecated), mac, vulns, tags list
A3: Shodan Datapedia - ntp page | B3: https://datapedia.shodan.io/property/ntp.html | C3: ntp fields and the monlist DDoS-reflection note
A4: Shodan Datapedia - protocol property pages | B4: https://datapedia.shodan.io/property/<name>.html | C4: Confirms each protocol/product property exists and lists its fields. Pages contain field tables and example data but mostly no prose
A5: Shodan blog - SSL update | B5: https://blog.shodan.io/ssl-update/ | C5: What the ssl property contains (cert, chain, versions, cipher)
A6: Knostic - How to find an MCP server with Shodan | B6: https://www.knostic.ai/blog/find-mcp-server-shodan | C6: How MCP servers are fingerprinted (initialize handshake)
A8: Honest limits: Datapedia protocol pages mostly give field tables, not written explanations. For those rows the description combines the field list from Datapedia with the standard public meaning of the protocol/product, and the 'Basis' column says so. Confidence 'High' = Datapedia or Shodan text states it; 'Medium' = listed by Datapedia, meaning from standard protocol knowledge or inferred.

Sheet Platform Use Summary
A1: Answer | B1: Top-level fields | C1: Sub-fields
A2: Yes | B2: =COUNTIF('Data Dictionary'!N2:N200,A2) -> 23 | C2: =COUNTIF('Sub-fields Observed'!F2:F200,A2) -> 4
A3: Partial | B3: =COUNTIF('Data Dictionary'!N2:N200,A3) -> 25 | C3: =COUNTIF('Sub-fields Observed'!F2:F200,A3) -> 7
A4: No | B4: =COUNTIF('Data Dictionary'!N2:N200,A4) -> 14 | C4: =COUNTIF('Sub-fields Observed'!F2:F200,A4) -> 13
A5: Total | B5: =SUM(B2:B4) -> 62 | C5: =SUM(C2:C4) -> 24
A7: Yes = clear signal for identifying, prioritising or targeting a business. Partial = useful only with other fields, low coverage, or narrow. No = engineering/duplicate/deprecated/empty. This is a design judgement from the field meanings and the 10-row sample, not something stated in the data. Confirm with a larger extract.
